Workbook

Sheet Repair and Maintenance asper CA
A1: S. no. | B1: Nature of defect or deficiency
A2: Carriageway and Paved Shoulder
A3: 1 | B3: Cracking < 5% subjected to limit of 0.5 sqm for any 50 m length
A4: 2 | B4: Rutting < 5 mm
A5: 3 | B5: Ravelling < 1% of area
A6: 4 | B6: Potholes - Nil
A7: 5 | B7: Roughness value exceeding 2,400 mm/km

Sheet Mar-25 Summary
A1: Total Length Surveyed (in lane km) | B1: 261.1
A4: Summary @100m interval | H4: Summary @50m interval
A5: Distress Type | B5: Permissible Limites as per CA | C5: Total Lane Length (in km) | D5: Rectification Lane Length (in km) | E5: Percentage Lane Length Affected (%) | F5: Common Rectification Lane length (Survey Month July-24 and March-25) | H5: Distress Type | I5: Permissible Limites as per CA | J5: Total Lane Length (in km) | K5: Rectification Lane Length (in km) | L5: Percentage Lane Length Affected (%) | M5: Common Rectification Lane length (Survey Month July-24 and March-25)
A6: Roughness | B6: 2400 mm/km | C6: 261.1 | D6: 6.37 | E6: =D6/C6 -> 0.024396783 | F6: 2.58 | H6: Roughness | I6: 2400 mm/km | J6: 261.1 | K6: 6.37 | L6: =K6/J6 -> 0.024396783 | M6: 2.58
A7: Rutting | B7: 5 mm | C7: 261.1 | D7: 15.92 | E7: =D7/C7 -> 0.060972807 | F7: 14.8 | H7: Rutting | I7: 5 mm | J7: 261.1 | K7: 15.92 | L7: =K7/J7 -> 0.060972807 | M7: 14.8
A8: Cracking | B8: 0.05 | C8: 261.1 | D8: 0.3 | E8: =D8/C8 -> 0.0011489851 | F8: 0 | H8: Cracking | I8: 0.05 | J8: 261.1 | K8: 0.35 | L8: =K8/J8 -> 0.0013404826 | M8: 0.5
A9: Ravelling | B9: 0.01 | C9: 261.1 | D9: 0.7 | E9: =D9/C9 -> 0.0026809651 | F9: 0.4 | H9: Ravelling | I9: 0.01 | J9: 261.1 | K9: 0.7 | L9: =K9/J9 -> 0.0026809651 | M9: 0.4
A10: All 4 Distress | C10: 261.1 | D10: 23.19 | E10: =D10/C10 -> 0.088816545 | H10: All 4 Distress | J10: 261.1 | K10: 23.29 | L10: =K10/J10 -> 0.08919954
A11: Interval for the cracking is mentioned as 50m interval in contract agreement, but for analysis purpose all distress are calculated at 100m interval. | H11: Interval for cracking is calculated at 50m interval as mentioned in contract agreement
A13: Since in agreement permissible limit for roughness is not specified, the permissible limits has been taken form MoRT&H Circular no. RW/NH-33044/88/2021-S&R(P&B)/DNT(215840) Dated 29th March 2023 which specifies the maximum permissible limit is 2400 mm/km for Flexible Pavement. | H13: Since in agreement permissible limit for roughness is not specified, the permissible limits has been taken form MoRT&H Circular no. RW/NH-33044/88/2021-S&R(P&B)/DNT(215840) Dated 29th March 2023 which specifies the maximum permissible limit is 2400 mm/km for Flexible Pavement.

Sheet Roughness,Rut,Crack,Ravelling
A1: NH Number | B1: Start Chainage | C1: End Chainage | D1: Length | E1: Structure Details | F1: Roughness | S1: Rut Depth | AB1: Cracking | AL1: Ravelling
F2: Limitation of BI as per Concession Agreement (in mm/km) | G2: L1 | J2: L2 | M2: R1 | P2: R2 | S2: Limitation of Rut Depth as per Concession Agreement (in mm) | T2: L1 | V2: L2 | X2: R1 | Z2: R2 | AB2: Limitation of Cracking as per Concession Agreement (in % Area) | AC2: L1 | AE2: L2 | AH2: R1 | AJ2: R2 | AL2: Limitation of Ravelling as per Concession Agreement (in Sq m) | AM2: L1 | AO2: L2 | AQ2: R1 | AS2: R2
G3: Lane Roughness IRI (in m/km) | H3: Lane Roughness BI (in mm/km) | I3: Remark | J3: Lane Roughness IRI (in m/km) | K3: Lane Roughness BI (in mm/km) | L3: Remark | M3: Lane Roughness IRI (in m/km) | N3: Lane Roughness BI (in mm/km) | O3: Remark | P3: Lane Roughness IRI (in m/km) | Q3: Lane Roughness BI (in mm/km) | R3: Remark | T3: Rut Depth (in mm) | U3: Remark | V3: Rut Depth (in mm) | W3: Remark | X3: Rut Depth (in mm) | Y3: Remark | Z3: Rut Depth (in mm) | AA3: Remark | AC3: % Area | AD3: Remark | AE3: % Area | AF3: Remark | AH3: % Area | AI3: Remark | AJ3: % Area | AK3: Remark | AM3: Area (Sq m) | AN3: Remark | AO3: Area (Sq m) | AP3: Remark | AQ3: Area (Sq m) | AR3: Remark | AS3: Area (Sq m) | AT3: Remark
A4: NH-65 | B4: 249000 | C4: 249100 | D4: =C4-B4 -> 100 | F4: 2500 | G4: 5.675 | H4: =630*G4^1.12 -> 4403.341 | I4: =IF(H4>F4,"Rectification Required"," - ") -> Rectification Required | J4: 5.99 | K4: =630*J4^1.12 -> 4677.9825 | L4: =IF(K4>F4,"Rectification Required"," - ") -> Rectification Required | M4: 3.675 | N4: =630*M4^1.12 -> 2706.6293 | O4: =IF(N4>F4,"Rectification Required"," - ") -> Rectification Required | P4: 4.045 | Q4: =630*P4^1.12 -> 3013.6256 | R4: =IF(Q4>F4,"Rectification Required"," - ") -> Rectification Required | S4: 10 | T4: 11.8 | U4: =IF(T4>S4,"Rectification Required"," - ") -> Rectification Required | V4: 7.65 | W4: =IF(V4>S4,"Rectification Required"," - ") -> - | X4: 11.15 | Y4: =IF(X4>S4,"Rectification Required"," - ") -> Rectification Required | Z4: 5.2 | AA4: =IF(Z4>S4,"Rectification Required"," - ") -> - | AB4: 5 | AC4: 1.7652214 | AD4: =IF(AC4>AB4,"Rectification Required"," - ") -> - | AE4: 13.861845 | AF4: =IF(AE4>AB4,"Rectification Required"," - ") -> Rectification Required | AG4: 600 | AH4: 2.3269146 | AI4: =IF(AH4>AB4,"Rectification Required"," - ") -> - | AJ4: 17.840847 | AK4: =IF(AJ4>AB4,"Rectification Required"," - ") -> Rectification Required | AL4: 10 | AM4: 23.91 | AN4: =IF(AM4>AL4,"Rectification Required"," - ") -> Rectification Required | AO4: 22.51 | AP4: =IF(AO4>AL4,"Rectification Required"," - ") -> Rectification Required | AQ4: 39.61 | AR4: =IF(AQ4>AL4,"Rectification Required"," - ") -> Rectification Required | AS4: 15.154 | AT4: =IF(AS4>AL4,"Rectification Required"," - ") -> Rectification Required
A5: NH-65 | B5: 249100 | C5: 249200 | D5: =C5-B5 -> 100 | F5: 2500 | G5: 4.605 | H5: =630*G5^1.12 -> 3484.6386 | I5: =IF(H5>F5,"Rectification Required"," - ") -> Rectification Required | J5: 2.915 | K5: =630*J5^1.12 -> 2088.0252 | L5: =IF(K5>F5,"Rectification Required"," - ") -> - | M5: 5.275 | N5: =630*M5^1.12 -> 4057.2308 | O5: =IF(N5>F5,"Rectification Required"," - ") -> Rectification Required | P5: 3.24 | Q5: =630*P5^1.12 -> 2350.4497 | R5: =IF(Q5>F5,"Rectification Required"," - ") -> - | S5: 10 | T5: 11.8 | U5: =IF(T5>S5,"Rectification Required"," - ") -> Rectification Required | V5: 5.5 | W5: =IF(V5>S5,"Rectification Required"," - ") -> - | X5: 13.3 | Y5: =IF(X5>S5,"Rectification Required"," - ") -> Rectification Required | Z5: 2.6 | AA5: =IF(Z5>S5,"Rectification Required"," - ") -> - | AB5: 5 | AC5: 9.1530449 | AD5: =IF(AC5>AB5,"Rectification Required"," - ") -> Rectification Required | AE5: 28.346107 | AF5: =IF(AE5>AB5,"Rectification Required"," - ") -> Rectification Required | AG5: 599 | AH5: 10.733031 | AI5: =IF(AH5>AB5,"Rectification Required"," - ") -> Rectification Required | AJ5: 0.032578286 | AK5: =IF(AJ5>AB5,"Rectification Required"," - ") -> - | AL5: 10 | AM5: 28.509 | AN5: =IF(AM5>AL5,"Rectification Required"," - ") -> Rectification Required | AO5: 28.298 | AP5: =IF(AO5>AL5,"Rectification Required"," - ") -> Rectification Required | AQ5: 32.352 | AR5: =IF(AQ5>AL5,"Rectification Required"," - ") -> Rectification Required | AS5: 25.789 | AT5: =IF(AS5>AL5,"Rectification Required"," - ") -> Rectification Required
A6: NH-65 | B6: 249200 | C6: 249300 | D6: =C6-B6 -> 100 | F6: 2500 | G6: 7.85 | H6: =630*G6^1.12 -> 6332.7824 | I6: =IF(H6>F6,"Rectification Required"," - ") -> Rectification Required | J6: 4 | K6: =630*J6^1.12 -> 2976.1015 | L6: =IF(K6>F6,"Rectification Required"," - ") -> Rectification Required | M6: 4.02 | N6: =630*M6^1.12 -> 2992.7727 | O6: =IF(N6>F6,"Rectification Required"," - ") -> Rectification Required | P6: 3.45 | Q6: =630*P6^1.12 -> 2521.7262 | R6: =IF(Q6>F6,"Rectification Required"," - ") -> Rectification Required | S6: 10 | T6: 11.65 | U6: =IF(T6>S6,"Rectification Required"," - ") -> Rectification Required | V6: 4.25 | W6: =IF(V6>S6,"Rectification Required"," - ") -> - | X6: 2.85 | Y6: =IF(X6>S6,"Rectification Required"," - ") -> - | Z6: 1.55 | AA6: =IF(Z6>S6,"Rectification Required"," - ") -> - | AB6: 5 | AC6: 46.573171 | AD6: =IF(AC6>AB6,"Rectification Required"," - ") -> Rectification Required | AE6: 8.8543029 | AF6: =IF(AE6>AB6,"Rectification Required"," - ") -> Rectification Required | AG6: 598 | AH6: 2.5864386 | AI6: =IF(AH6>AB6,"Rectification Required"," - ") -> - | AJ6: 0.0078931429 | AK6: =IF(AJ6>AB6,"Rectification Required"," - ") -> - | AL6: 10 | AM6: 20.032 | AN6: =IF(AM6>AL6,"Rectification Required"," - ") -> Rectification Required | AO6: 25.613 | AP6: =IF(AO6>AL6,"Rectification Required"," - ") -> Rectification Required | AQ6: 36.544 | AR6: =IF(AQ6>AL6,"Rectification Required"," - ") -> Rectification Required | AS6: 27.085 | AT6: =IF(AS6>AL6,"Rectification Required"," - ") -> Rectification Required
A7: NH-65 | B7: 249300 | C7: 249400 | D7: =C7-B7 -> 100 | F7: 2500 | G7: 6.31 | H7: =630*G7^1.12 -> 4958.7639 | I7: =IF(H7>F7,"Rectification Required"," - ") -> Rectification Required | J7: 4.92 | K7: =630*J7^1.12 -> 3752.6794 | L7: =IF(K7>F7,"Rectification Required"," - ") -> Rectification Required | M7: 5.14 | N7: =630*M7^1.12 -> 3941.1162 | O7: =IF(N7>F7,"Rectification Required"," - ") -> Rectification Required | P7: 2.85 | Q7: =630*P7^1.12 -> 2035.9485 | R7: =IF(Q7>F7,"Rectification Required"," - ") -> - | S7: 10 | T7: 13.65 | U7: =IF(T7>S7,"Rectification Required"," - ") -> Rectification Required | V7: 2.05 | W7: =IF(V7>S7,"Rectification Required"," - ") -> - | X7: 5.25 | Y7: =IF(X7>S7,"Rectification Required"," - ") -> - | Z7: 1.8 | AA7: =IF(Z7>S7,"Rectification Required"," - ") -> - | AB7: 5 | AC7: 8.0585691 | AD7: =IF(AC7>AB7,"Rectification Required"," - ") -> Rectification Required | AE7: 2.0181417 | AF7: =IF(AE7>AB7,"Rectification Required"," - ") -> - | AG7: 597 | AH7: 0.90498143 | AI7: =IF(AH7>AB7,"Rectification Required"," - ") -> - | AJ7: 1.3879631 | AK7: =IF(AJ7>AB7,"Rectification Required"," - ") -> - | AL7: 10 | AM7: 24 | AN7: =IF(AM7>AL7,"Rectification Required"," - ") -> Rectification Required | AO7: 21.03 | AP7: =IF(AO7>AL7,"Rectification Required"," - ") -> Rectification Required | AQ7: 41.155 | AR7: =IF(AQ7>AL7,"Rectification Required"," - ") -> Rectification Required | AS7: 34.948 | AT7: =IF(AS7>AL7,"Rectification Required"," - ") -> Rectification Required
A8: NH-65 | B8: 249400 | C8: 249500 | D8: =C8-B8 -> 100 | F8: 2500 | G8: 3.93 | H8: =630*G8^1.12 -> 2917.8315 | I8: =IF(H8>F8,"Rectification Required"," - ") -> Rectification Required | J8: 3.32 | K8: =630*J8^1.12 -> 2415.5454 | L8: =IF(K8>F8,"Rectification Required"," - ") -> - | M8: 4.85 | N8: =630*M8^1.12 -> 3692.9319 | O8: =IF(N8>F8,"Rectification Required"," - ") -> Rectification Required | P8: 4.06 | Q8: =630*P8^1.12 -> 3026.1448 | R8: =IF(Q8>F8,"Rectification Required"," - ") -> Rectification Required | S8: 10 | T8: 16.95 | U8: =IF(T8>S8,"Rectification Required"," - ") -> Rectification Required | V8: 2 | W8: =IF(V8>S8,"Rectification Required"," - ") -> - | X8: 3.55 | Y8: =IF(X8>S8,"Rectification Required"," - ") -> - | Z8: 1.35 | AA8: =IF(Z8>S8,"Rectification Required"," - ") -> - | AB8: 5 | AC8: 19.531054 | AD8: =IF(AC8>AB8,"Rectification Required"," - ") -> Rectification Required | AE8: 0.0071791429 | AF8: =IF(AE8>AB8,"Rectification Required"," - ") -> - | AG8: 596 | AH8: 0.26386657 | AI8: =IF(AH8>AB8,"Rectification Required"," - ") -> - | AJ8: 0.19490914 | AK8: =IF(AJ8>AB8,"Rectification Required"," - ") -> - | AL8: 10 | AM8: 25.342 | AN8: =IF(AM8>AL8,"Rectification Required"," - ") -> Rectification Required | AO8: 24.501 | AP8: =IF(AO8>AL8,"Rectification Required"," - ") -> Rectification Required | AQ8: 40.931 | AR8: =IF(AQ8>AL8,"Rectification Required"," - ") -> Rectification Required | AS8: 38.721 | AT8: =IF(AS8>AL8,"Rectification Required"," - ") -> Rectification Required
A9: NH-65 | B9: 249500 | C9: 249600 | D9: =C9-B9 -> 100 | F9: 2500 | G9: 5.855 | H9: =630*G9^1.12 -> 4560.0613 | I9: =IF(H9>F9,"Rectification Required"," - ") -> Rectification Required | J9: 3.335 | K9: =630*J9^1.12 -> 2427.7719 | L9: =IF(K9>F9,"Rectification Required"," - ") -> - | M9: 4.45 | N9: =630*M9^1.12 -> 3353.5421 | O9: =IF(N9>F9,"Rectification Required"," - ") -> Rectification Required | P9: 3.525 | Q9: =630*P9^1.12 -> 2583.2044 | R9: =IF(Q9>F9,"Rectification Required"," - ") -> Rectification Required | S9: 10 | T9: 13.4 | U9: =IF(T9>S9,"Rectification Required"," - ") -> Rectification Required | V9: 3.75 | W9: =IF(V9>S9,"Rectification Required"," - ") -> - | X9: 3.75 | Y9: =IF(X9>S9,"Rectification Required"," - ") -> - | Z9: 1.45 | AA9: =IF(Z9>S9,"Rectification Required"," - ") -> - | AB9: 5 | AC9: 22.507092 | AD9: =IF(AC9>AB9,"Rectification Required"," - ") -> Rectification Required | AE9: 8.7812291 | AF9: =IF(AE9>AB9,"Rectification Required"," - ") -> Rectification Required | AG9: 595 | AH9: 0.031524286 | AI9: =IF(AH9>AB9,"Rectification Required"," - ") -> - | AJ9: 0.0036202857 | AK9: =IF(AJ9>AB9,"Rectification Required"," - ") -> - | AL9: 10 | AM9: 28.829 | AN9: =IF(AM9>AL9,"Rectification Required"," - ") -> Rectification Required | AO9: 29.411 | AP9: =IF(AO9>AL9,"Rectification Required"," - ") -> Rectification Required | AQ9: 36.148 | AR9: =IF(AQ9>AL9,"Rectification Required"," - ") -> Rectification Required | AS9: 34.632 | AT9: =IF(AS9>AL9,"Rectification Required"," - ") -> Rectification Required
A10: NH-65 | B10: 249600 | C10: 249700 | D10: =C10-B10 -> 100 | F10: 2500 | G10: 3.69 | H10: =630*G10^1.12 -> 2719.0055 | I10: =IF(H10>F10,"Rectification Required"," - ") -> Rectification Required | J10: 4.19 | K10: =630*J10^1.12 -> 3134.8752 | L10: =IF(K10>F10,"Rectification Required"," - ") -> Rectification Required | M10: 3.75 | N10: =630*M10^1.12 -> 2768.5704 | O10: =IF(N10>F10,"Rectification Required"," - ") -> Rectification Required | P10: 3.535 | Q10: =630*P10^1.12 -> 2591.4134 | R10: =IF(Q10>F10,"Rectification Required"," - ") -> Rectification Required | S10: 10 | T10: 4.1 | U10: =IF(T10>S10,"Rectification Required"," - ") -> - | V10: 4.4 | W10: =IF(V10>S10,"Rectification Required"," - ") -> - | X10: 5.45 | Y10: =IF(X10>S10,"Rectification Required"," - ") -> - | Z10: 1.6 | AA10: =IF(Z10>S10,"Rectification Required"," - ") -> - | AB10: 5 | AC10: 0.0053168571 | AD10: =IF(AC10>AB10,"Rectification Required"," - ") -> - | AE10: 3.0089137 | AF10: =IF(AE10>AB10,"Rectification Required"," - ") -> - | AG10: 594 | AH10: 0.020573714 | AI10: =IF(AH10>AB10,"Rectification Required"," - ") -> - | AJ10: 0.018676286 | AK10: =IF(AJ10>AB10,"Rectification Required"," - ") -> - | AL10: 10 | AM10: 43.552 | AN10: =IF(AM10>AL10,"Rectification Required"," - ") -> Rectification Required | AO10: 31.685 | AP10: =IF(AO10>AL10,"Rectification Required"," - ") -> Rectification Required | AQ10: 36.967 | AR10: =IF(AQ10>AL10,"Rectification Required"," - ") -> Rectification Required | AS10: 31.114 | AT10: =IF(AS10>AL10,"Rectification Required"," - ") -> Rectification Required
A11: NH-65 | B11: 249700 | C11: 249800 | D11: =C11-B11 -> 100 | F11: 2500 | G11: 3.27 | H11: =630*G11^1.12 -> 2374.8382 | I11: =IF(H11>F11,"Rectification Required"," - ") -> - | J11: 4.235 | K11: =630*J11^1.12 -> 3172.6077 | L11: =IF(K11>F11,"Rectification Required"," - ") -> Rectification Required | M11: 4.185 | N11: =630*M11^1.12 -> 3130.6857 | O11: =IF(N11>F11,"Rectification Required"," - ") -> Rectification Required | P11: 3.27 | Q11: =630*P11^1.12 -> 2374.8382 | R11: =IF(Q11>F11,"Rectification Required"," - ") -> - | S11: 10 | T11: 1.9 | U11: =IF(T11>S11,"Rectification Required"," - ") -> - | V11: 3.9 | W11: =IF(V11>S11,"Rectification Required"," - ") -> - | X11: 14.1 | Y11: =IF(X11>S11,"Rectification Required"," - ") -> Rectification Required | Z11: 1.55 | AA11: =IF(Z11>S11,"Rectification Required"," - ") -> - | AB11: 5 | AC11: 0.0036945714 | AD11: =IF(AC11>AB11,"Rectification Required"," - ") -> - | AE11: 0.0033485714 | AF11: =IF(AE11>AB11,"Rectification Required"," - ") -> - | AG11: 593 | AH11: 6.9771254 | AI11: =IF(AH11>AB11,"Rectification Required"," - ") -> Rectification Required | AJ11: 0.0065671429 | AK11: =IF(AJ11>AB11,"Rectification Required"," - ") -> - | AL11: 10 | AM11: 43.82 | AN11: =IF(AM11>AL11,"Rectification Required"," - ") -> Rectification Required | AO11: 31.224 | AP11: =IF(AO11>AL11,"Rectification Required"," - ") -> Rectification Required | AQ11: 32.961 | AR11: =IF(AQ11>AL11,"Rectification Required"," - ") -> Rectification Required | AS11: 32.309 | AT11: =IF(AS11>AL11,"Rectification Required"," - ") -> Rectification Required
A12: NH-65 | B12: 249800 | C12: 249900 | D12: =C12-B12 -> 100 | F12: 2500 | G12: 3.905 | H12: =630*G12^1.12 -> 2897.0508 | I12: =IF(H12>F12,"Rectification Required"," - ") -> Rectification Required | J12: 3.275 | K12: =630*J12^1.12 -> 2378.9056 | L12: =IF(K12>F12,"Rectification Required"," - ") -> - | M12: 5.205 | N12: =630*M12^1.12 -> 3996.9781 | O12: =IF(N12>F12,"Rectification Required"," - ") -> Rectification Required | P12: 3.835 | Q12: =630*P12^1.12 -> 2838.9501 | R12: =IF(Q12>F12,"Rectification Required"," - ") -> Rectification Required | S12: 10 | T12: 2.2 | U12: =IF(T12>S12,"Rectification Required"," - ") -> - | V12: 2.2 | W12: =IF(V12>S12,"Rectification Required"," - ") -> - | X12: 9.05 | Y12: =IF(X12>S12,"Rectification Required"," - ") -> - | Z12: 2.2 | AA12: =IF(Z12>S12,"Rectification Required"," - ") -> - | AB12: 5 | AC12: 1.5585657 | AD12: =IF(AC12>AB12,"Rectification Required"," - ") -> - | AE12: 0.00082085714 | AF12: =IF(AE12>AB12,"Rectification Required"," - ") -> - | AG12: 592 | AH12: 1.7386497 | AI12: =IF(AH12>AB12,"Rectification Required"," - ") -> - | AJ12: 2.4055346 | AK12: =IF(AJ12>AB12,"Rectification Required"," - ") -> - | AL12: 10 | AM12: 43.071 | AN12: =IF(AM12>AL12,"Rectification Required"," - ") -> Rectification Required | AO12: 27.274 | AP12: =IF(AO12>AL12,"Rectification Required"," - ") -> Rectification Required | AQ12: 18.428 | AR12: =IF(AQ12>AL12,"Rectification Required"," - ") -> Rectification Required | AS12: 29.178 | AT12: =IF(AS12>AL12,"Rectification Required"," - ") -> Rectification Required
A13: NH-65 | B13: 249900 | C13: 250000 | D13: =C13-B13 -> 100 | F13: 2500 | G13: 3.18 | H13: =630*G13^1.12 -> 2301.7541 | I13: =IF(H13>F13,"Rectification Required"," - ") -> - | J13: 3.825 | K13: =630*J13^1.12 -> 2830.6604 | L13: =IF(K13>F13,"Rectification Required"," - ") -> Rectification Required | M13: 5.36 | N13: =630*M13^1.12 -> 4130.5237 | O13: =IF(N13>F13,"Rectification Required"," - ") -> Rectification Required | P13: 4.29 | Q13: =630*P13^1.12 -> 3218.7905 | R13: =IF(Q13>F13,"Rectification Required"," - ") -> Rectification Required | S13: 10 | T13: 1.85 | U13: =IF(T13>S13,"Rectification Required"," - ") -> - | V13: 2.75 | W13: =IF(V13>S13,"Rectification Required"," - ") -> - | X13: 7.05 | Y13: =IF(X13>S13,"Rectification Required"," - ") -> - | Z13: 2.25 | AA13: =IF(Z13>S13,"Rectification Required"," - ") -> - | AB13: 5 | AC13: 0.0074851429 | AD13: =IF(AC13>AB13,"Rectification Required"," - ") -> - | AE13: 0.0019828571 | AF13: =IF(AE13>AB13,"Rectification Required"," - ") -> - | AG13: 591 | AH13: 2.5284994 | AI13: =IF(AH13>AB13,"Rectification Required"," - ") -> - | AJ13: 0.018235714 | AK13: =IF(AJ13>AB13,"Rectification Required"," - ") -> - | AL13: 10 | AM13: 42.916 | AN13: =IF(AM13>AL13,"Rectification Required"," - ") -> Rectification Required | AO13: 30.385 | AP13: =IF(AO13>AL13,"Rectification Required"," - ") -> Rectification Required | AQ13: 30.057 | AR13: =IF(AQ13>AL13,"Rectification Required"," - ") -> Rectification Required | AS13: 25.625 | AT13: =IF(AS13>AL13,"Rectification Required"," - ") -> Rectification Required
A14: NH-65 | B14: 250000 | C14: 250100 | D14: =C14-B14 -> 100 | F14: 2500 | G14: 4.275 | H14: =630*G14^1.12 -> 3206.1881 | I14: =IF(H14>F14,"Rectification Required"," - ") -> Rectification Required | J14: 4.455 | K14: =630*J14^1.12 -> 3357.7626 | L14: =IF(K14>F14,"Rectification Required"," - ") -> Rectification Required | M14: 6.59 | N14: =630*M14^1.12 -> 5205.8568 | O14: =IF(N14>F14,"Rectification Required"," - ") -> Rectification Required | P14: 5.045 | Q14: =630*P14^1.12 -> 3859.6246 | R14: =IF(Q14>F14,"Rectification Required"," - ") -> Rectification Required | S14: 10 | T14: 2.6 | U14: =IF(T14>S14,"Rectification Required"," - ") -> - | V14: 3 | W14: =IF(V14>S14,"Rectification Required"," - ") -> - | X14: 7.4 | Y14: =IF(X14>S14,"Rectification Required"," - ") -> - | Z14: 1.8 | AA14: =IF(Z14>S14,"Rectification Required"," - ") -> - | AB14: 5 | AC14: 0.41040029 | AD14: =IF(AC14>AB14,"Rectification Required"," - ") -> - | AE14: 0.01088 | AF14: =IF(AE14>AB14,"Rectification Required"," - ") -> - | AG14: 590 | AH14: 0.17151543 | AI14: =IF(AH14>AB14,"Rectification Required"," - ") -> - | AJ14: 0.0024762857 | AK14: =IF(AJ14>AB14,"Rectification Required"," - ") -> - | AL14: 10 | AM14: 44.005 | AN14: =IF(AM14>AL14,"Rectification Required"," - ") -> Rectification Required | AO14: 30.291 | AP14: =IF(AO14>AL14,"Rectification Required"," - ") -> Rectification Required | AQ14: 24.386 | AR14: =IF(AQ14>AL14,"Rectification Required"," - ") -> Rectification Required | AS14: 19.596 | AT14: =IF(AS14>AL14,"Rectification Required"," - ") -> Rectification Required
A15: NH-65 | B15: 250100 | C15: 250200 | D15: =C15-B15 -> 100 | F15: 2500 | G15: 4.74 | H15: =630*G15^1.12 -> 3599.2523 | I15: =IF(H15>F15,"Rectification Required"," - ") -> Rectification Required | J15: 3.075 | K15: =630*J15^1.12 -> 2216.8029 | L15: =IF(K15>F15,"Rectification Required"," - ") -> - | M15: 4.945 | N15: =630*M15^1.12 -> 3774.0426 | O15: =IF(N15>F15,"Rectification Required"," - ") -> Rectification Required | P15: 5.445 | Q15: =630*P15^1.12 -> 4203.9562 | R15: =IF(Q15>F15,"Rectification Required"," - ") -> Rectification Required | S15: 10 | T15: 4.95 | U15: =IF(T15>S15,"Rectification Required"," - ") -> - | V15: 2.45 | W15: =IF(V15>S15,"Rectification Required"," - ") -> - | X15: 15.95 | Y15: =IF(X15>S15,"Rectification Required"," - ") -> Rectification Required | Z15: 2.5 | AA15: =IF(Z15>S15,"Rectification Required"," - ") -> - | AB15: 5 | AC15: 0.014874571 | AD15: =IF(AC15>AB15,"Rectification Required"," - ") -> - | AE15: 0.017098857 | AF15: =IF(AE15>AB15,"Rectification Required"," - ") -> - | AG15: 589 | AH15: 6.2334211 | AI15: =IF(AH15>AB15,"Rectification Required"," - ") -> Rectification Required | AJ15: 0.027054571 | AK15: =IF(AJ15>AB15,"Rectification Required"," - ") -> - | AL15: 10 | AM15: 45.462 | AN15: =IF(AM15>AL15,"Rectification Required"," - ") -> Rectification Required | AO15: 29.481 | AP15: =IF(AO15>AL15,"Rectification Required"," - ") -> Rectification Required | AQ15: 28.712 | AR15: =IF(AQ15>AL15,"Rectification Required"," - ") -> Rectification Required | AS15: 22.598 | AT15: =IF(AS15>AL15,"Rectification Required"," - ") -> Rectification Required
... A374: NH-65 | B374: 286000 | C374: 286100 | D374: =C374-B374 -> 100 | F374: 2500 | G374: 2.935 | H374: =630*G374^1.12 -> 2104.077 | I374: =IF(H374>F374,"Rectification Required"," - ") -> - | J374: 4.565 | K374: =630*J374^1.12 -> 3450.7558 | L374: =IF(K374>F374,"Rectification Required"," - ") -> Rectification Required | M374: 2.81 | N374: =630*M374^1.12 -> 2003.9719 | O374: =IF(N374>F374,"Rectification Required"," - ") -> - | P374: 2.57 | Q374: =630*P374^1.12 -> 1813.2832 | R374: =IF(Q374>F374,"Rectification Required"," - ") -> - | S374: 10 | T374: 5.75 | U374: =IF(T374>S374,"Rectification Required"," - ") -> - | V374: 5 | W374: =IF(V374>S374,"Rectification Required"," - ") -> - | X374: 4.95 | Y374: =IF(X374>S374,"Rectification Required"," - ") -> - | Z374: 5.45 | AA374: =IF(Z374>S374,"Rectification Required"," - ") -> - | AB374: 5 | AC374: 7.616356 | AD374: =IF(AC374>AB374,"Rectification Required"," - ") -> Rectification Required | AE374: 4.5304283 | AF374: =IF(AE374>AB374,"Rectification Required"," - ") -> - | AG374: 230 | AH374: 0.0066922857 | AI374: =IF(AH374>AB374,"Rectification Required"," - ") -> - | AJ374: 11.981817 | AK374: =IF(AJ374>AB374,"Rectification Required"," - ") -> Rectification Required | AL374: 10 | AM374: 27.075 | AN374: =IF(AM374>AL374,"Rectification Required"," - ") -> Rectification Required | AO374: 26.991 | AP374: =IF(AO374>AL374,"Rectification Required"," - ") -> Rectification Required | AQ374: 33.843 | AR374: =IF(AQ374>AL374,"Rectification Required"," - ") -> Rectification Required | AS374: 15.983 | AT374: =IF(AS374>AL374,"Rectification Required"," - ") -> Rectification Required
A375: NH-65 | B375: 286100 | C375: 286200 | D375: =C375-B375 -> 100 | F375: 2500 | G375: 1.58 | H375: =630*G375^1.12 -> 1051.5659 | I375: =IF(H375>F375,"Rectification Required"," - ") -> - | J375: 2.73 | K375: =630*J375^1.12 -> 1940.1831 | L375: =IF(K375>F375,"Rectification Required"," - ") -> - | M375: UC | N375: =630*M375^1.12 -> #VALUE! | O375: =IF(N375>F375,"Rectification Required"," - ") -> #VALUE! | P375: UC | Q375: =630*P375^1.12 -> #VALUE! | R375: =IF(Q375>F375,"Rectification Required"," - ") -> #VALUE! | S375: 10 | T375: 5.3 | U375: =IF(T375>S375,"Rectification Required"," - ") -> - | V375: 6.4 | W375: =IF(V375>S375,"Rectification Required"," - ") -> - | X375: 0 | Y375: =IF(X375>S375,"Rectification Required"," - ") -> - | Z375: 0 | AA375: =IF(Z375>S375,"Rectification Required"," - ") -> - | AB375: 5 | AC375: 18.375875 | AD375: =IF(AC375>AB375,"Rectification Required"," - ") -> Rectification Required | AE375: 25.136565 | AF375: =IF(AE375>AB375,"Rectification Required"," - ") -> Rectification Required | AG375: 229 | AH375: 0 | AI375: =IF(AH375>AB375,"Rectification Required"," - ") -> - | AJ375: 0 | AK375: =IF(AJ375>AB375,"Rectification Required"," - ") -> - | AL375: 10 | AM375: 8.199 | AN375: =IF(AM375>AL375,"Rectification Required"," - ") -> - | AO375: 9.259 | AP375: =IF(AO375>AL375,"Rectification Required"," - ") -> - | AQ375: 19.2 | AR375: =IF(AQ375>AL375,"Rectification Required"," - ") -> Rectification Required | AS375: 12.831 | AT375: =IF(AS375>AL375,"Rectification Required"," - ") -> Rectification Required
A376: NH-65 | B376: 286200 | C376: 286300 | D376: =C376-B376 -> 100 | F376: 2500 | G376: 0 | H376: =630*G376^1.12 -> 0 | I376: =IF(H376>F376,"Rectification Required"," - ") -> - | J376: 0 | K376: =630*J376^1.12 -> 0 | L376: =IF(K376>F376,"Rectification Required"," - ") -> - | M376: 0 | N376: =630*M376^1.12 -> 0 | O376: =IF(N376>F376,"Rectification Required"," - ") -> - | P376: 0 | Q376: =630*P376^1.12 -> 0 | R376: =IF(Q376>F376,"Rectification Required"," - ") -> - | S376: 10 | T376: 0 | U376: =IF(T376>S376,"Rectification Required"," - ") -> - | V376: 0 | W376: =IF(V376>S376,"Rectification Required"," - ") -> - | X376: 0 | Y376: =IF(X376>S376,"Rectification Required"," - ") -> - | Z376: 0 | AA376: =IF(Z376>S376,"Rectification Required"," - ") -> - | AB376: 5 | AC376: 0 | AD376: =IF(AC376>AB376,"Rectification Required"," - ") -> - | AE376: 0 | AF376: =IF(AE376>AB376,"Rectification Required"," - ") -> - | AG376: 228 | AH376: 0 | AI376: =IF(AH376>AB376,"Rectification Required"," - ") -> - | AJ376: 0 | AK376: =IF(AJ376>AB376,"Rectification Required"," - ") -> - | AL376: 10 | AM376: 0 | AN376: =IF(AM376>AL376,"Rectification Required"," - ") -> - | AO376: 0 | AP376: =IF(AO376>AL376,"Rectification Required"," - ") -> - | AQ376: 0 | AR376: =IF(AQ376>AL376,"Rectification Required"," - ") -> - | AS376: 0 | AT376: =IF(AS376>AL376,"Rectification Required"," - ") -> -
A377: NH-65 | B377: 286300 | C377: 286400 | D377: =C377-B377 -> 100 | F377: 2500 | G377: 0 | H377: =630*G377^1.12 -> 0 | I377: =IF(H377>F377,"Rectification Required"," - ") -> - | J377: 0 | K377: =630*J377^1.12 -> 0 | L377: =IF(K377>F377,"Rectification Required"," - ") -> - | M377: 0 | N377: =630*M377^1.12 -> 0 | O377: =IF(N377>F377,"Rectification Required"," - ") -> - | P377: 0 | Q377: =630*P377^1.12 -> 0 | R377: =IF(Q377>F377,"Rectification Required"," - ") -> - | S377: 10 | T377: 0 | U377: =IF(T377>S377,"Rectification Required"," - ") -> - | V377: 0 | W377: =IF(V377>S377,"Rectification Required"," - ") -> - | X377: 0 | Y377: =IF(X377>S377,"Rectification Required"," - ") -> - | Z377: 0 | AA377: =IF(Z377>S377,"Rectification Required"," - ") -> - | AB377: 5 | AC377: 0 | AD377: =IF(AC377>AB377,"Rectification Required"," - ") -> - | AE377: 0 | AF377: =IF(AE377>AB377,"Rectification Required"," - ") -> - | AG377: 227 | AH377: 0 | AI377: =IF(AH377>AB377,"Rectification Required"," - ") -> - | AJ377: 0 | AK377: =IF(AJ377>AB377,"Rectification Required"," - ") -> - | AL377: 10 | AM377: 0 | AN377: =IF(AM377>AL377,"Rectification Required"," - ") -> - | AO377: 0 | AP377: =IF(AO377>AL377,"Rectification Required"," - ") -> - | AQ377: 0 | AR377: =IF(AQ377>AL377,"Rectification Required"," - ") -> - | AS377: 0 | AT377: =IF(AS377>AL377,"Rectification Required"," - ") -> -
A378: NH-65 | B378: 286400 | C378: 286500 | D378: =C378-B378 -> 100 | F378: 2500 | G378: 0 | H378: =630*G378^1.12 -> 0 | I378: =IF(H378>F378,"Rectification Required"," - ") -> - | J378: 0 | K378: =630*J378^1.12 -> 0 | L378: =IF(K378>F378,"Rectification Required"," - ") -> - | M378: 0 | N378: =630*M378^1.12 -> 0 | O378: =IF(N378>F378,"Rectification Required"," - ") -> - | P378: 0 | Q378: =630*P378^1.12 -> 0 | R378: =IF(Q378>F378,"Rectification Required"," - ") -> - | S378: 10 | T378: 0 | U378: =IF(T378>S378,"Rectification Required"," - ") -> - | V378: 0 | W378: =IF(V378>S378,"Rectification Required"," - ") -> - | X378: 0 | Y378: =IF(X378>S378,"Rectification Required"," - ") -> - | Z378: 0 | AA378: =IF(Z378>S378,"Rectification Required"," - ") -> - | AB378: 5 | AC378: 0 | AD378: =IF(AC378>AB378,"Rectification Required"," - ") -> - | AE378: 0 | AF378: =IF(AE378>AB378,"Rectification Required"," - ") -> - | AG378: 226 | AH378: 0 | AI378: =IF(AH378>AB378,"Rectification Required"," - ") -> - | AJ378: 0 | AK378: =IF(AJ378>AB378,"Rectification Required"," - ") -> - | AL378: 10 | AM378: 0 | AN378: =IF(AM378>AL378,"Rectification Required"," - ") -> - | AO378: 0 | AP378: =IF(AO378>AL378,"Rectification Required"," - ") -> - | AQ378: 0 | AR378: =IF(AQ378>AL378,"Rectification Required"," - ") -> - | AS378: 0 | AT378: =IF(AS378>AL378,"Rectification Required"," - ") -> -
A379: NH-65 | B379: 286500 | C379: 286600 | D379: =C379-B379 -> 100 | F379: 2500 | G379: 0 | H379: =630*G379^1.12 -> 0 | I379: =IF(H379>F379,"Rectification Required"," - ") -> - | J379: 0 | K379: =630*J379^1.12 -> 0 | L379: =IF(K379>F379,"Rectification Required"," - ") -> - | M379: 0 | N379: =630*M379^1.12 -> 0 | O379: =IF(N379>F379,"Rectification Required"," - ") -> - | P379: 0 | Q379: =630*P379^1.12 -> 0 | R379: =IF(Q379>F379,"Rectification Required"," - ") -> - | S379: 10 | T379: 0 | U379: =IF(T379>S379,"Rectification Required"," - ") -> - | V379: 0 | W379: =IF(V379>S379,"Rectification Required"," - ") -> - | X379: 0 | Y379: =IF(X379>S379,"Rectification Required"," - ") -> - | Z379: 0 | AA379: =IF(Z379>S379,"Rectification Required"," - ") -> - | AB379: 5 | AC379: 0 | AD379: =IF(AC379>AB379,"Rectification Required"," - ") -> - | AE379: 0 | AF379: =IF(AE379>AB379,"Rectification Required"," - ") -> - | AG379: 225 | AH379: 0 | AI379: =IF(AH379>AB379,"Rectification Required"," - ") -> - | AJ379: 0 | AK379: =IF(AJ379>AB379,"Rectification Required"," - ") -> - | AL379: 10 | AM379: 0 | AN379: =IF(AM379>AL379,"Rectification Required"," - ") -> - | AO379: 0 | AP379: =IF(AO379>AL379,"Rectification Required"," - ") -> - | AQ379: 0 | AR379: =IF(AQ379>AL379,"Rectification Required"," - ") -> - | AS379: 0 | AT379: =IF(AS379>AL379,"Rectification Required"," - ") -> -
A380: NH-65 | B380: 286600 | C380: 286700 | D380: =C380-B380 -> 100 | F380: 2500 | G380: 0 | H380: =630*G380^1.12 -> 0 | I380: =IF(H380>F380,"Rectification Required"," - ") -> - | J380: 0 | K380: =630*J380^1.12 -> 0 | L380: =IF(K380>F380,"Rectification Required"," - ") -> - | M380: 0 | N380: =630*M380^1.12 -> 0 | O380: =IF(N380>F380,"Rectification Required"," - ") -> - | P380: 0 | Q380: =630*P380^1.12 -> 0 | R380: =IF(Q380>F380,"Rectification Required"," - ") -> - | S380: 10 | T380: 0 | U380: =IF(T380>S380,"Rectification Required"," - ") -> - | V380: 0 | W380: =IF(V380>S380,"Rectification Required"," - ") -> - | X380: 0 | Y380: =IF(X380>S380,"Rectification Required"," - ") -> - | Z380: 0 | AA380: =IF(Z380>S380,"Rectification Required"," - ") -> - | AB380: 5 | AC380: 0 | AD380: =IF(AC380>AB380,"Rectification Required"," - ") -> - | AE380: 0 | AF380: =IF(AE380>AB380,"Rectification Required"," - ") -> - | AG380: 224 | AH380: 0 | AI380: =IF(AH380>AB380,"Rectification Required"," - ") -> - | AJ380: 0 | AK380: =IF(AJ380>AB380,"Rectification Required"," - ") -> - | AL380: 10 | AM380: 0 | AN380: =IF(AM380>AL380,"Rectification Required"," - ") -> - | AO380: 0 | AP380: =IF(AO380>AL380,"Rectification Required"," - ") -> - | AQ380: 0 | AR380: =IF(AQ380>AL380,"Rectification Required"," - ") -> - | AS380: 0 | AT380: =IF(AS380>AL380,"Rectification Required"," - ") -> -
A381: NH-65 | B381: 286700 | C381: 286800 | D381: =C381-B381 -> 100 | F381: 2500 | G381: 0 | H381: =630*G381^1.12 -> 0 | I381: =IF(H381>F381,"Rectification Required"," - ") -> - | J381: 0 | K381: =630*J381^1.12 -> 0 | L381: =IF(K381>F381,"Rectification Required"," - ") -> - | M381: 0 | N381: =630*M381^1.12 -> 0 | O381: =IF(N381>F381,"Rectification Required"," - ") -> - | P381: 0 | Q381: =630*P381^1.12 -> 0 | R381: =IF(Q381>F381,"Rectification Required"," - ") -> - | S381: 10 | T381: 0 | U381: =IF(T381>S381,"Rectification Required"," - ") -> - | V381: 0 | W381: =IF(V381>S381,"Rectification Required"," - ") -> - | X381: 0 | Y381: =IF(X381>S381,"Rectification Required"," - ") -> - | Z381: 0 | AA381: =IF(Z381>S381,"Rectification Required"," - ") -> - | AB381: 5 | AC381: 0 | AD381: =IF(AC381>AB381,"Rectification Required"," - ") -> - | AE381: 0 | AF381: =IF(AE381>AB381,"Rectification Required"," - ") -> - | AG381: 223 | AH381: 0 | AI381: =IF(AH381>AB381,"Rectification Required"," - ") -> - | AJ381: 0 | AK381: =IF(AJ381>AB381,"Rectification Required"," - ") -> - | AL381: 10 | AM381: 0 | AN381: =IF(AM381>AL381,"Rectification Required"," - ") -> - | AO381: 0 | AP381: =IF(AO381>AL381,"Rectification Required"," - ") -> - | AQ381: 0 | AR381: =IF(AQ381>AL381,"Rectification Required"," - ") -> - | AS381: 0 | AT381: =IF(AS381>AL381,"Rectification Required"," - ") -> -
A382: NH-65 | B382: 286800 | C382: 286900 | D382: =C382-B382 -> 100 | F382: 2500 | G382: 0 | H382: =630*G382^1.12 -> 0 | I382: =IF(H382>F382,"Rectification Required"," - ") -> - | J382: 0 | K382: =630*J382^1.12 -> 0 | L382: =IF(K382>F382,"Rectification Required"," - ") -> - | M382: 0 | N382: =630*M382^1.12 -> 0 | O382: =IF(N382>F382,"Rectification Required"," - ") -> - | P382: 0 | Q382: =630*P382^1.12 -> 0 | R382: =IF(Q382>F382,"Rectification Required"," - ") -> - | S382: 10 | T382: 0 | U382: =IF(T382>S382,"Rectification Required"," - ") -> - | V382: 0 | W382: =IF(V382>S382,"Rectification Required"," - ") -> - | X382: 0 | Y382: =IF(X382>S382,"Rectification Required"," - ") -> - | Z382: 0 | AA382: =IF(Z382>S382,"Rectification Required"," - ") -> - | AB382: 5 | AC382: 0 | AD382: =IF(AC382>AB382,"Rectification Required"," - ") -> - | AE382: 0 | AF382: =IF(AE382>AB382,"Rectification Required"," - ") -> - | AG382: 222 | AH382: 0 | AI382: =IF(AH382>AB382,"Rectification Required"," - ") -> - | AJ382: 0 | AK382: =IF(AJ382>AB382,"Rectification Required"," - ") -> - | AL382: 10 | AM382: 0 | AN382: =IF(AM382>AL382,"Rectification Required"," - ") -> - | AO382: 0 | AP382: =IF(AO382>AL382,"Rectification Required"," - ") -> - | AQ382: 0 | AR382: =IF(AQ382>AL382,"Rectification Required"," - ") -> - | AS382: 0 | AT382: =IF(AS382>AL382,"Rectification Required"," - ") -> -
A383: NH-65 | B383: 286900 | C383: 287000 | D383: =C383-B383 -> 100 | F383: 2500 | G383: 0 | H383: =630*G383^1.12 -> 0 | I383: =IF(H383>F383,"Rectification Required"," - ") -> - | J383: 0 | K383: =630*J383^1.12 -> 0 | L383: =IF(K383>F383,"Rectification Required"," - ") -> - | M383: 0 | N383: =630*M383^1.12 -> 0 | O383: =IF(N383>F383,"Rectification Required"," - ") -> - | P383: 0 | Q383: =630*P383^1.12 -> 0 | R383: =IF(Q383>F383,"Rectification Required"," - ") -> - | S383: 10 | T383: 0 | U383: =IF(T383>S383,"Rectification Required"," - ") -> - | V383: 0 | W383: =IF(V383>S383,"Rectification Required"," - ") -> - | X383: 0 | Y383: =IF(X383>S383,"Rectification Required"," - ") -> - | Z383: 0 | AA383: =IF(Z383>S383,"Rectification Required"," - ") -> - | AB383: 5 | AC383: 0 | AD383: =IF(AC383>AB383,"Rectification Required"," - ") -> - | AE383: 0 | AF383: =IF(AE383>AB383,"Rectification Required"," - ") -> - | AG383: 221 | AH383: 0 | AI383: =IF(AH383>AB383,"Rectification Required"," - ") -> - | AJ383: 0 | AK383: =IF(AJ383>AB383,"Rectification Required"," - ") -> - | AL383: 10 | AM383: 0 | AN383: =IF(AM383>AL383,"Rectification Required"," - ") -> - | AO383: 0 | AP383: =IF(AO383>AL383,"Rectification Required"," - ") -> - | AQ383: 0 | AR383: =IF(AQ383>AL383,"Rectification Required"," - ") -> - | AS383: 0 | AT383: =IF(AS383>AL383,"Rectification Required"," - ") -> -
A384: NH-65 | B384: 287000 | C384: 287100 | D384: =C384-B384 -> 100 | F384: 2500 | G384: 0 | H384: =630*G384^1.12 -> 0 | I384: =IF(H384>F384,"Rectification Required"," - ") -> - | J384: 0 | K384: =630*J384^1.12 -> 0 | L384: =IF(K384>F384,"Rectification Required"," - ") -> - | M384: 0 | N384: =630*M384^1.12 -> 0 | O384: =IF(N384>F384,"Rectification Required"," - ") -> - | P384: 0 | Q384: =630*P384^1.12 -> 0 | R384: =IF(Q384>F384,"Rectification Required"," - ") -> - | S384: 10 | T384: 0 | U384: =IF(T384>S384,"Rectification Required"," - ") -> - | V384: 0 | W384: =IF(V384>S384,"Rectification Required"," - ") -> - | X384: 0 | Y384: =IF(X384>S384,"Rectification Required"," - ") -> - | Z384: 0 | AA384: =IF(Z384>S384,"Rectification Required"," - ") -> - | AB384: 5 | AC384: 0 | AD384: =IF(AC384>AB384,"Rectification Required"," - ") -> - | AE384: 0 | AF384: =IF(AE384>AB384,"Rectification Required"," - ") -> - | AG384: 220 | AH384: 0 | AI384: =IF(AH384>AB384,"Rectification Required"," - ") -> - | AJ384: 0 | AK384: =IF(AJ384>AB384,"Rectification Required"," - ") -> - | AL384: 10 | AM384: 0 | AN384: =IF(AM384>AL384,"Rectification Required"," - ") -> - | AO384: 0 | AP384: =IF(AO384>AL384,"Rectification Required"," - ") -> - | AQ384: 0 | AR384: =IF(AQ384>AL384,"Rectification Required"," - ") -> - | AS384: 0 | AT384: =IF(AS384>AL384,"Rectification Required"," - ") -> -
A385: NH-65 | B385: 287100 | C385: 287200 | D385: =C385-B385 -> 100 | F385: 2500 | G385: 0 | H385: =630*G385^1.12 -> 0 | I385: =IF(H385>F385,"Rectification Required"," - ") -> - | J385: 0 | K385: =630*J385^1.12 -> 0 | L385: =IF(K385>F385,"Rectification Required"," - ") -> - | M385: 0 | N385: =630*M385^1.12 -> 0 | O385: =IF(N385>F385,"Rectification Required"," - ") -> - | P385: 0 | Q385: =630*P385^1.12 -> 0 | R385: =IF(Q385>F385,"Rectification Required"," - ") -> - | S385: 10 | T385: 0 | U385: =IF(T385>S385,"Rectification Required"," - ") -> - | V385: 0 | W385: =IF(V385>S385,"Rectification Required"," - ") -> - | X385: 0 | Y385: =IF(X385>S385,"Rectification Required"," - ") -> - | Z385: 0 | AA385: =IF(Z385>S385,"Rectification Required"," - ") -> - | AB385: 5 | AC385: 0 | AD385: =IF(AC385>AB385,"Rectification Required"," - ") -> - | AE385: 0 | AF385: =IF(AE385>AB385,"Rectification Required"," - ") -> - | AG385: 219 | AH385: 0 | AI385: =IF(AH385>AB385,"Rectification Required"," - ") -> - | AJ385: 0 | AK385: =IF(AJ385>AB385,"Rectification Required"," - ") -> - | AL385: 10 | AM385: 0 | AN385: =IF(AM385>AL385,"Rectification Required"," - ") -> - | AO385: 0 | AP385: =IF(AO385>AL385,"Rectification Required"," - ") -> - | AQ385: 0 | AR385: =IF(AQ385>AL385,"Rectification Required"," - ") -> - | AS385: 0 | AT385: =IF(AS385>AL385,"Rectification Required"," - ") -> -
A386: NH-65 | B386: 287200 | C386: 287300 | D386: =C386-B386 -> 100 | F386: 2500 | G386: 0 | H386: =630*G386^1.12 -> 0 | I386: =IF(H386>F386,"Rectification Required"," - ") -> - | J386: 0 | K386: =630*J386^1.12 -> 0 | L386: =IF(K386>F386,"Rectification Required"," - ") -> - | M386: 3.715 | N386: =630*M386^1.12 -> 2739.6458 | O386: =IF(N386>F386,"Rectification Required"," - ") -> Rectification Required | P386: 2.385 | Q386: =630*P386^1.12 -> 1667.7369 | R386: =IF(Q386>F386,"Rectification Required"," - ") -> - | S386: 10 | T386: 0 | U386: =IF(T386>S386,"Rectification Required"," - ") -> - | V386: 0 | W386: =IF(V386>S386,"Rectification Required"," - ") -> - | X386: 4.05 | Y386: =IF(X386>S386,"Rectification Required"," - ") -> - | Z386: 3.7 | AA386: =IF(Z386>S386,"Rectification Required"," - ") -> - | AB386: 5 | AC386: 0 | AD386: =IF(AC386>AB386,"Rectification Required"," - ") -> - | AE386: 0 | AF386: =IF(AE386>AB386,"Rectification Required"," - ") -> - | AG386: 218 | AH386: 2.680726 | AI386: =IF(AH386>AB386,"Rectification Required"," - ") -> - | AJ386: 1.0091017 | AK386: =IF(AJ386>AB386,"Rectification Required"," - ") -> - | AL386: 10 | AM386: 0 | AN386: =IF(AM386>AL386,"Rectification Required"," - ") -> - | AO386: 0 | AP386: =IF(AO386>AL386,"Rectification Required"," - ") -> - | AQ386: 21.934 | AR386: =IF(AQ386>AL386,"Rectification Required"," - ") -> Rectification Required | AS386: 28.871 | AT386: =IF(AS386>AL386,"Rectification Required"," - ") -> Rectification Required
A387: NH-65 | B387: 287300 | C387: 287400 | D387: =C387-B387 -> 100 | F387: 2500 | G387: 2.35 | H387: =630*G387^1.12 -> 1640.3501 | I387: =IF(H387>F387,"Rectification Required"," - ") -> - | J387: 3.42 | K387: =630*J387^1.12 -> 2497.1797 | L387: =IF(K387>F387,"Rectification Required"," - ") -> - | M387: 1.535 | N387: =630*M387^1.12 -> 1018.0801 | O387: =IF(N387>F387,"Rectification Required"," - ") -> - | P387: 1.655 | Q387: =630*P387^1.12 -> 1107.629 | R387: =IF(Q387>F387,"Rectification Required"," - ") -> - | S387: 10 | T387: 7.3 | U387: =IF(T387>S387,"Rectification Required"," - ") -> - | V387: 14.15 | W387: =IF(V387>S387,"Rectification Required"," - ") -> Rectification Required | X387: 8.2 | Y387: =IF(X387>S387,"Rectification Required"," - ") -> - | Z387: 7.45 | AA387: =IF(Z387>S387,"Rectification Required"," - ") -> - | AB387: 5 | AC387: 0.001714 | AD387: =IF(AC387>AB387,"Rectification Required"," - ") -> - | AE387: 0.0064554286 | AF387: =IF(AE387>AB387,"Rectification Required"," - ") -> - | AG387: 217 | AH387: 0.0013251429 | AI387: =IF(AH387>AB387,"Rectification Required"," - ") -> - | AJ387: 0.0037985714 | AK387: =IF(AJ387>AB387,"Rectification Required"," - ") -> - | AL387: 10 | AM387: 15.529 | AN387: =IF(AM387>AL387,"Rectification Required"," - ") -> Rectification Required | AO387: 25.46 | AP387: =IF(AO387>AL387,"Rectification Required"," - ") -> Rectification Required | AQ387: 24.848 | AR387: =IF(AQ387>AL387,"Rectification Required"," - ") -> Rectification Required | AS387: 34.145 | AT387: =IF(AS387>AL387,"Rectification Required"," - ") -> Rectification Required
... A394: NH-65 | B394: 288000 | C394: 288100 | D394: =C394-B394 -> 100 | F394: 2500 | G394: 2.99 | H394: =630*G394^1.12 -> 2148.2869 | I394: =IF(H394>F394,"Rectification Required"," - ") -> - | J394: 3.825 | K394: =630*J394^1.12 -> 2830.6604 | L394: =IF(K394>F394,"Rectification Required"," - ") -> Rectification Required | M394: 5.125 | N394: =630*M394^1.12 -> 3928.237 | O394: =IF(N394>F394,"Rectification Required"," - ") -> Rectification Required | P394: 4.505 | Q394: =630*P394^1.12 -> 3399.9985 | R394: =IF(Q394>F394,"Rectification Required"," - ") -> Rectification Required | S394: 10 | T394: 7.5 | U394: =IF(T394>S394,"Rectification Required"," - ") -> - | V394: 2.8 | W394: =IF(V394>S394,"Rectification Required"," - ") -> - | X394: 15.3 | Y394: =IF(X394>S394,"Rectification Required"," - ") -> Rectification Required | Z394: 11.65 | AA394: =IF(Z394>S394,"Rectification Required"," - ") -> Rectification Required | AB394: 5 | AC394: 0.62387429 | AD394: =IF(AC394>AB394,"Rectification Required"," - ") -> - | AE394: 0 | AF394: =IF(AE394>AB394,"Rectification Required"," - ") -> - | AG394: 210 | AH394: 0.0027148571 | AI394: =IF(AH394>AB394,"Rectification Required"," - ") -> - | AJ394: 2.5874606 | AK394: =IF(AJ394>AB394,"Rectification Required"," - ") -> - | AL394: 10 | AM394: 41.934 | AN394: =IF(AM394>AL394,"Rectification Required"," - ") -> Rectification Required | AO394: 37.321 | AP394: =IF(AO394>AL394,"Rectification Required"," - ") -> Rectification Required | AQ394: 23.462 | AR394: =IF(AQ394>AL394,"Rectification Required"," - ") -> Rectification Required | AS394: 25.422 | AT394: =IF(AS394>AL394,"Rectification Required"," - ") -> Rectification Required
A395: NH-65 | B395: 288100 | C395: 288200 | D395: =C395-B395 -> 100 | F395: 2500 | G395: 3.83 | H395: =630*G395^1.12 -> 2834.8049 | I395: =IF(H395>F395,"Rectification Required"," - ") -> Rectification Required | J395: 4.07 | K395: =630*J395^1.12 -> 3034.494 | L395: =IF(K395>F395,"Rectification Required"," - ") -> Rectification Required | M395: UC | N395: =630*M395^1.12 -> #VALUE! | O395: =IF(N395>F395,"Rectification Required"," - ") -> #VALUE! | P395: UC | Q395: =630*P395^1.12 -> #VALUE! | R395: =IF(Q395>F395,"Rectification Required"," - ") -> #VALUE! | S395: 10 | T395: 5.35 | U395: =IF(T395>S395,"Rectification Required"," - ") -> - | V395: 5.35 | W395: =IF(V395>S395,"Rectification Required"," - ") -> - | X395: 0 | Y395: =IF(X395>S395,"Rectification Required"," - ") -> - | Z395: 0 | AA395: =IF(Z395>S395,"Rectification Required"," - ") -> - | AB395: 5 | AC395: 2.3135834 | AD395: =IF(AC395>AB395,"Rectification Required"," - ") -> - | AE395: 4.2638189 | AF395: =IF(AE395>AB395,"Rectification Required"," - ") -> - | AG395: 209 | AH395: 0 | AI395: =IF(AH395>AB395,"Rectification Required"," - ") -> - | AJ395: 0 | AK395: =IF(AJ395>AB395,"Rectification Required"," - ") -> - | AL395: 10 | AM395: 31.859 | AN395: =IF(AM395>AL395,"Rectification Required"," - ") -> Rectification Required | AO395: 23.027 | AP395: =IF(AO395>AL395,"Rectification Required"," - ") -> Rectification Required | AQ395: 25.699 | AR395: =IF(AQ395>AL395,"Rectification Required"," - ") -> Rectification Required | AS395: 19.825 | AT395: =IF(AS395>AL395,"Rectification Required"," - ") -> Rectification Required
A396: NH-65 | B396: 288200 | C396: 288300 | D396: =C396-B396 -> 100 | F396: 2500 | G396: 0 | H396: =630*G396^1.12 -> 0 | I396: =IF(H396>F396,"Rectification Required"," - ") -> - | J396: 0 | K396: =630*J396^1.12 -> 0 | L396: =IF(K396>F396,"Rectification Required"," - ") -> - | M396: 0 | N396: =630*M396^1.12 -> 0 | O396: =IF(N396>F396,"Rectification Required"," - ") -> - | P396: 0 | Q396: =630*P396^1.12 -> 0 | R396: =IF(Q396>F396,"Rectification Required"," - ") -> - | S396: 10 | T396: 0 | U396: =IF(T396>S396,"Rectification Required"," - ") -> - | V396: 0 | W396: =IF(V396>S396,"Rectification Required"," - ") -> - | X396: 0 | Y396: =IF(X396>S396,"Rectification Required"," - ") -> - | Z396: 0 | AA396: =IF(Z396>S396,"Rectification Required"," - ") -> - | AB396: 5 | AC396: 0 | AD396: =IF(AC396>AB396,"Rectification Required"," - ") -> - | AE396: 0 | AF396: =IF(AE396>AB396,"Rectification Required"," - ") -> - | AG396: 208 | AH396: 0 | AI396: =IF(AH396>AB396,"Rectification Required"," - ") -> - | AJ396: 0 | AK396: =IF(AJ396>AB396,"Rectification Required"," - ") -> - | AL396: 10 | AM396: 0 | AN396: =IF(AM396>AL396,"Rectification Required"," - ") -> - | AO396: 0 | AP396: =IF(AO396>AL396,"Rectification Required"," - ") -> - | AQ396: 0 | AR396: =IF(AQ396>AL396,"Rectification Required"," - ") -> - | AS396: 0 | AT396: =IF(AS396>AL396,"Rectification Required"," - ") -> -
A397: NH-65 | B397: 288300 | C397: 288400 | D397: =C397-B397 -> 100 | F397: 2500 | G397: 0 | H397: =630*G397^1.12 -> 0 | I397: =IF(H397>F397,"Rectification Required"," - ") -> - | J397: 0 | K397: =630*J397^1.12 -> 0 | L397: =IF(K397>F397,"Rectification Required"," - ") -> - | M397: 0 | N397: =630*M397^1.12 -> 0 | O397: =IF(N397>F397,"Rectification Required"," - ") -> - | P397: 0 | Q397: =630*P397^1.12 -> 0 | R397: =IF(Q397>F397,"Rectification Required"," - ") -> - | S397: 10 | T397: 0 | U397: =IF(T397>S397,"Rectification Required"," - ") -> - | V397: 0 | W397: =IF(V397>S397,"Rectification Required"," - ") -> - | X397: 0 | Y397: =IF(X397>S397,"Rectification Required"," - ") -> - | Z397: 0 | AA397: =IF(Z397>S397,"Rectification Required"," - ") -> - | AB397: 5 | AC397: 0 | AD397: =IF(AC397>AB397,"Rectification Required"," - ") -> - | AE397: 0 | AF397: =IF(AE397>AB397,"Rectification Required"," - ") -> - | AG397: 207 | AH397: 0 | AI397: =IF(AH397>AB397,"Rectification Required"," - ") -> - | AJ397: 0 | AK397: =IF(AJ397>AB397,"Rectification Required"," - ") -> - | AL397: 10 | AM397: 0 | AN397: =IF(AM397>AL397,"Rectification Required"," - ") -> - | AO397: 0 | AP397: =IF(AO397>AL397,"Rectification Required"," - ") -> - | AQ397: 0 | AR397: =IF(AQ397>AL397,"Rectification Required"," - ") -> - | AS397: 0 | AT397: =IF(AS397>AL397,"Rectification Required"," - ") -> -
A398: NH-65 | B398: 288400 | C398: 288500 | D398: =C398-B398 -> 100 | F398: 2500 | G398: 0 | H398: =630*G398^1.12 -> 0 | I398: =IF(H398>F398,"Rectification Required"," - ") -> - | J398: 0 | K398: =630*J398^1.12 -> 0 | L398: =IF(K398>F398,"Rectification Required"," - ") -> - | M398: 0 | N398: =630*M398^1.12 -> 0 | O398: =IF(N398>F398,"Rectification Required"," - ") -> - | P398: 0 | Q398: =630*P398^1.12 -> 0 | R398: =IF(Q398>F398,"Rectification Required"," - ") -> - | S398: 10 | T398: 0 | U398: =IF(T398>S398,"Rectification Required"," - ") -> - | V398: 0 | W398: =IF(V398>S398,"Rectification Required"," - ") -> - | X398: 0 | Y398: =IF(X398>S398,"Rectification Required"," - ") -> - | Z398: 0 | AA398: =IF(Z398>S398,"Rectification Required"," - ") -> - | AB398: 5 | AC398: 0 | AD398: =IF(AC398>AB398,"Rectification Required"," - ") -> - | AE398: 0 | AF398: =IF(AE398>AB398,"Rectification Required"," - ") -> - | AG398: 206 | AH398: 0 | AI398: =IF(AH398>AB398,"Rectification Required"," - ") -> - | AJ398: 0 | AK398: =IF(AJ398>AB398,"Rectification Required"," - ") -> - | AL398: 10 | AM398: 0 | AN398: =IF(AM398>AL398,"Rectification Required"," - ") -> - | AO398: 0 | AP398: =IF(AO398>AL398,"Rectification Required"," - ") -> - | AQ398: 0 | AR398: =IF(AQ398>AL398,"Rectification Required"," - ") -> - | AS398: 0 | AT398: =IF(AS398>AL398,"Rectification Required"," - ") -> -
A399: NH-65 | B399: 288500 | C399: 288600 | D399: =C399-B399 -> 100 | F399: 2500 | G399: 0 | H399: =630*G399^1.12 -> 0 | I399: =IF(H399>F399,"Rectification Required"," - ") -> - | J399: 0 | K399: =630*J399^1.12 -> 0 | L399: =IF(K399>F399,"Rectification Required"," - ") -> - | M399: 0 | N399: =630*M399^1.12 -> 0 | O399: =IF(N399>F399,"Rectification Required"," - ") -> - | P399: 0 | Q399: =630*P399^1.12 -> 0 | R399: =IF(Q399>F399,"Rectification Required"," - ") -> - | S399: 10 | T399: 0 | U399: =IF(T399>S399,"Rectification Required"," - ") -> - | V399: 0 | W399: =IF(V399>S399,"Rectification Required"," - ") -> - | X399: 0 | Y399: =IF(X399>S399,"Rectification Required"," - ") -> - | Z399: 0 | AA399: =IF(Z399>S399,"Rectification Required"," - ") -> - | AB399: 5 | AC399: 0 | AD399: =IF(AC399>AB399,"Rectification Required"," - ") -> - | AE399: 0 | AF399: =IF(AE399>AB399,"Rectification Required"," - ") -> - | AG399: 205 | AH399: 0 | AI399: =IF(AH399>AB399,"Rectification Required"," - ") -> - | AJ399: 0 | AK399: =IF(AJ399>AB399,"Rectification Required"," - ") -> - | AL399: 10 | AM399: 0 | AN399: =IF(AM399>AL399,"Rectification Required"," - ") -> - | AO399: 0 | AP399: =IF(AO399>AL399,"Rectification Required"," - ") -> - | AQ399: 0 | AR399: =IF(AQ399>AL399,"Rectification Required"," - ") -> - | AS399: 0 | AT399: =IF(AS399>AL399,"Rectification Required"," - ") -> -
A400: NH-65 | B400: 288600 | C400: 288700 | D400: =C400-B400 -> 100 | F400: 2500 | G400: 0 | H400: =630*G400^1.12 -> 0 | I400: =IF(H400>F400,"Rectification Required"," - ") -> - | J400: 0 | K400: =630*J400^1.12 -> 0 | L400: =IF(K400>F400,"Rectification Required"," - ") -> - | M400: 0 | N400: =630*M400^1.12 -> 0 | O400: =IF(N400>F400,"Rectification Required"," - ") -> - | P400: 0 | Q400: =630*P400^1.12 -> 0 | R400: =IF(Q400>F400,"Rectification Required"," - ") -> - | S400: 10 | T400: 0 | U400: =IF(T400>S400,"Rectification Required"," - ") -> - | V400: 0 | W400: =IF(V400>S400,"Rectification Required"," - ") -> - | X400: 0 | Y400: =IF(X400>S400,"Rectification Required"," - ") -> - | Z400: 0 | AA400: =IF(Z400>S400,"Rectification Required"," - ") -> - | AB400: 5 | AC400: 0 | AD400: =IF(AC400>AB400,"Rectification Required"," - ") -> - | AE400: 0 | AF400: =IF(AE400>AB400,"Rectification Required"," - ") -> - | AG400: 204 | AH400: 0 | AI400: =IF(AH400>AB400,"Rectification Required"," - ") -> - | AJ400: 0 | AK400: =IF(AJ400>AB400,"Rectification Required"," - ") -> - | AL400: 10 | AM400: 0 | AN400: =IF(AM400>AL400,"Rectification Required"," - ") -> - | AO400: 0 | AP400: =IF(AO400>AL400,"Rectification Required"," - ") -> - | AQ400: 0 | AR400: =IF(AQ400>AL400,"Rectification Required"," - ") -> - | AS400: 0 | AT400: =IF(AS400>AL400,"Rectification Required"," - ") -> -
A401: NH-65 | B401: 288700 | C401: 288800 | D401: =C401-B401 -> 100 | F401: 2500 | G401: 0 | H401: =630*G401^1.12 -> 0 | I401: =IF(H401>F401,"Rectification Required"," - ") -> - | J401: 0 | K401: =630*J401^1.12 -> 0 | L401: =IF(K401>F401,"Rectification Required"," - ") -> - | M401: 0 | N401: =630*M401^1.12 -> 0 | O401: =IF(N401>F401,"Rectification Required"," - ") -> - | P401: 0 | Q401: =630*P401^1.12 -> 0 | R401: =IF(Q401>F401,"Rectification Required"," - ") -> - | S401: 10 | T401: 0 | U401: =IF(T401>S401,"Rectification Required"," - ") -> - | V401: 0 | W401: =IF(V401>S401,"Rectification Required"," - ") -> - | X401: 0 | Y401: =IF(X401>S401,"Rectification Required"," - ") -> - | Z401: 0 | AA401: =IF(Z401>S401,"Rectification Required"," - ") -> - | AB401: 5 | AC401: 0 | AD401: =IF(AC401>AB401,"Rectification Required"," - ") -> - | AE401: 0 | AF401: =IF(AE401>AB401,"Rectification Required"," - ") -> - | AG401: 203 | AH401: 0 | AI401: =IF(AH401>AB401,"Rectification Required"," - ") -> - | AJ401: 0 | AK401: =IF(AJ401>AB401,"Rectification Required"," - ") -> - | AL401: 10 | AM401: 0 | AN401: =IF(AM401>AL401,"Rectification Required"," - ") -> - | AO401: 0 | AP401: =IF(AO401>AL401,"Rectification Required"," - ") -> - | AQ401: 0 | AR401: =IF(AQ401>AL401,"Rectification Required"," - ") -> - | AS401: 0 | AT401: =IF(AS401>AL401,"Rectification Required"," - ") -> -
A402: NH-65 | B402: 288800 | C402: 288900 | D402: =C402-B402 -> 100 | F402: 2500 | G402: 0 | H402: =630*G402^1.12 -> 0 | I402: =IF(H402>F402,"Rectification Required"," - ") -> - | J402: 0 | K402: =630*J402^1.12 -> 0 | L402: =IF(K402>F402,"Rectification Required"," - ") -> - | M402: 0 | N402: =630*M402^1.12 -> 0 | O402: =IF(N402>F402,"Rectification Required"," - ") -> - | P402: 0 | Q402: =630*P402^1.12 -> 0 | R402: =IF(Q402>F402,"Rectification Required"," - ") -> - | S402: 10 | T402: 0 | U402: =IF(T402>S402,"Rectification Required"," - ") -> - | V402: 0 | W402: =IF(V402>S402,"Rectification Required"," - ") -> - | X402: 0 | Y402: =IF(X402>S402,"Rectification Required"," - ") -> - | Z402: 0 | AA402: =IF(Z402>S402,"Rectification Required"," - ") -> - | AB402: 5 | AC402: 0 | AD402: =IF(AC402>AB402,"Rectification Required"," - ") -> - | AE402: 0 | AF402: =IF(AE402>AB402,"Rectification Required"," - ") -> - | AG402: 202 | AH402: 0 | AI402: =IF(AH402>AB402,"Rectification Required"," - ") -> - | AJ402: 0 | AK402: =IF(AJ402>AB402,"Rectification Required"," - ") -> - | AL402: 10 | AM402: 0 | AN402: =IF(AM402>AL402,"Rectification Required"," - ") -> - | AO402: 0 | AP402: =IF(AO402>AL402,"Rectification Required"," - ") -> - | AQ402: 0 | AR402: =IF(AQ402>AL402,"Rectification Required"," - ") -> - | AS402: 0 | AT402: =IF(AS402>AL402,"Rectification Required"," - ") -> -
A403: NH-65 | B403: 288900 | C403: 289000 | D403: =C403-B403 -> 100 | F403: 2500 | G403: 0 | H403: =630*G403^1.12 -> 0 | I403: =IF(H403>F403,"Rectification Required"," - ") -> - | J403: 0 | K403: =630*J403^1.12 -> 0 | L403: =IF(K403>F403,"Rectification Required"," - ") -> - | M403: 0 | N403: =630*M403^1.12 -> 0 | O403: =IF(N403>F403,"Rectification Required"," - ") -> - | P403: 0 | Q403: =630*P403^1.12 -> 0 | R403: =IF(Q403>F403,"Rectification Required"," - ") -> - | S403: 10 | T403: 0 | U403: =IF(T403>S403,"Rectification Required"," - ") -> - | V403: 0 | W403: =IF(V403>S403,"Rectification Required"," - ") -> - | X403: 0 | Y403: =IF(X403>S403,"Rectification Required"," - ") -> - | Z403: 0 | AA403: =IF(Z403>S403,"Rectification Required"," - ") -> - | AB403: 5 | AC403: 0 | AD403: =IF(AC403>AB403,"Rectification Required"," - ") -> - | AE403: 0 | AF403: =IF(AE403>AB403,"Rectification Required"," - ") -> - | AG403: 201 | AH403: 0 | AI403: =IF(AH403>AB403,"Rectification Required"," - ") -> - | AJ403: 0 | AK403: =IF(AJ403>AB403,"Rectification Required"," - ") -> - | AL403: 10 | AM403: 0 | AN403: =IF(AM403>AL403,"Rectification Required"," - ") -> - | AO403: 0 | AP403: =IF(AO403>AL403,"Rectification Required"," - ") -> - | AQ403: 0 | AR403: =IF(AQ403>AL403,"Rectification Required"," - ") -> - | AS403: 0 | AT403: =IF(AS403>AL403,"Rectification Required"," - ") -> -
A404: NH-65 | B404: 289000 | C404: 289100 | D404: =C404-B404 -> 100 | F404: 2500 | G404: 0 | H404: =630*G404^1.12 -> 0 | I404: =IF(H404>F404,"Rectification Required"," - ") -> - | J404: 0 | K404: =630*J404^1.12 -> 0 | L404: =IF(K404>F404,"Rectification Required"," - ") -> - | M404: 0 | N404: =630*M404^1.12 -> 0 | O404: =IF(N404>F404,"Rectification Required"," - ") -> - | P404: 0 | Q404: =630*P404^1.12 -> 0 | R404: =IF(Q404>F404,"Rectification Required"," - ") -> - | S404: 10 | T404: 0 | U404: =IF(T404>S404,"Rectification Required"," - ") -> - | V404: 0 | W404: =IF(V404>S404,"Rectification Required"," - ") -> - | X404: 0 | Y404: =IF(X404>S404,"Rectification Required"," - ") -> - | Z404: 0 | AA404: =IF(Z404>S404,"Rectification Required"," - ") -> - | AB404: 5 | AC404: 0 | AD404: =IF(AC404>AB404,"Rectification Required"," - ") -> - | AE404: 0 | AF404: =IF(AE404>AB404,"Rectification Required"," - ") -> - | AG404: 200 | AH404: 0 | AI404: =IF(AH404>AB404,"Rectification Required"," - ") -> - | AJ404: 0 | AK404: =IF(AJ404>AB404,"Rectification Required"," - ") -> - | AL404: 10 | AM404: 0 | AN404: =IF(AM404>AL404,"Rectification Required"," - ") -> - | AO404: 0 | AP404: =IF(AO404>AL404,"Rectification Required"," - ") -> - | AQ404: 0 | AR404: =IF(AQ404>AL404,"Rectification Required"," - ") -> - | AS404: 0 | AT404: =IF(AS404>AL404,"Rectification Required"," - ") -> -
...

Sheet Mar-25 Comparision with CA@100m
